<?xml version="1.0" encoding="utf-8"?>
<mujoco>
	<compiler angle="radian" coordinate="local" meshdir="../stls/fetch" texturedir="../textures"></compiler>
	<option timestep="0.002">
		<flag warmstart="enable"></flag>
	</option>

	<include file="shared.xml"></include>

	<worldbody>
		<geom name="floor0" pos="0.8 0.75 0" size="0.85 0.7 1" type="plane" condim="3" material="floor_mat"></geom>
		<body name="floor0" pos="0.8 0.75 0">
			<site name="target0" pos="0 0 0.5" size="0.02 0.02 0.02" rgba="1 0 0 0" type="sphere"></site>
		</body>

		<include file="robot.xml"></include>

		<body pos="1.3 0.75 0.2" name="table0">
			<geom size="0.25 0.35 0.2" type="box" mass="2000" material="table_mat"></geom>
		</body>

		<body name="frame" pos="-0.107339 0.0435293 0.447376" user="1001 0 2002 -0.4 -0.1 0.252 0 0.3 0.45">
        <inertial pos="0.29 0 0" quat="0.5 0.5 0.5 0.5" mass="7.85398" diaginertia="0.923301 0.764585 0.168533" />
        <geom size="0.05 0.25" pos="0.6 0 0" type="cylinder" material="MatWood" rgba="1 0 0 1" />
        <geom size="0.05 0.25" pos="-0.02 0 0" type="cylinder" material="MatWood" rgba="1 0 0 1" />
        <site name="S_handle_target" pos="0.75 -0.5 -.18" size="0.025" group='3'/>
        <body name="door" pos="0.29 0 0">
            <inertial pos="0.0296816 -0.00152345 0" quat="0.701072 0 0 0.713091" mass="2.43455" diaginertia="0.0913751 0.0521615 0.043714" />
            <joint name="door_hinge" pos="0.31 0 0" axis="0 0 1" range="0 1.57" damping="1" frictionloss="2" />
            <geom size="0.2 0.05 0.25" type="box" friction="1 1 1" material="MatWood" />
            <geom size="0.05 0.25" pos="0.2 0 0" type="cylinder" material="MatWood" />
            <geom size="0.05 0.25" pos="-0.2 0 0" type="cylinder" material="MatWood" />
            <body name="latch" pos="-0.15 0 -0.025">
                <inertial pos="-0.017762 0.0138544 0" quat="0.365653 0.605347 -0.36522 0.605365" mass="3.53743" diaginertia="0.0483771 0.0410001 0.0111013" />
                <joint name="latch" pos="0 0 0" axis="0 1 0" range="0 1.8" frictionloss="5" />
                <geom size="0.05 0.15" quat="0.707388 0.706825 0 0" type="cylinder" material="MatFoil" />
                <geom size="0.02 0.1" pos="0.1 -0.15 0" quat="0.707388 0 0.706825 0" type="capsule" material="MatFoil" />
                <geom size="0.04 0.07" pos="-0.1 0.1 0" quat="0.707388 0 0.706825 0" type="capsule" material="MatFoil" />
                <site name="S_handle" pos="0.15 -0.15 0" size="0.025" group='3'/>
            </body>
        </body>
    </body>

		<light directional="true" ambient="0.2 0.2 0.2" diffuse="0.8 0.8 0.8" specular="0.3 0.3 0.3" castshadow="false" pos="0 0 4" dir="0 0 -1" name="light0"></light>
	</worldbody>

	<actuator>
		<position ctrllimited="true" ctrlrange="0 0.2" joint="robot0:l_gripper_finger_joint" kp="30000" name="robot0:l_gripper_finger_joint" user="1"></position>
		<position ctrllimited="true" ctrlrange="0 0.2" joint="robot0:r_gripper_finger_joint" kp="30000" name="robot0:r_gripper_finger_joint" user="1"></position>
	</actuator>
</mujoco>
